<?xml version="1.0"?>
<robot name="rosmaster_x3">

    <link name="base_footprint"/>

    <!-- base_link inertia needs modified -->
    <link name="base_link">
        <visual>
            <origin xyz="0 0 0.0" rpy="0 0 0"/>
            <geometry>
                <box size="0.238 0.1386 0.159"/>
            </geometry>
            <material name="white">
      	        <color rgba="1 1 1 0.9" /> 
            </material>
        </visual>
        <collision>
            <origin xyz="0 0 0.0" rpy="0 0 0"/>
            <geometry>
                <box size="0.238 0.1386 0.159"/>
            </geometry>
            <material name="white">
      	        <color rgba="1 1 1 0.9" /> 
            </material>
        </collision>
        <inertial>
            <mass value="4.6"/>
            <inertia ixx="0.0122666" ixy="0" ixz="0" iyy="0.0122666" iyz="0" izz="0.02"/>
        </inertial>
    </link>
    
    <joint name="base_joint" type="fixed">
        <parent link="base_footprint"/>
        <child link="base_link"/>
        <origin xyz="0.0 0.0 0.1145" rpy="0 0 0"/>
    </joint>

    <link name="laser_link">
        <visual>
            <origin xyz="0 0 0" rpy="0 0 0"/>
            <geometry>
                <cylinder length="0.025" radius="0.035"/>
            </geometry>
            <material name="black">
                <color rgba="0.0 0.0 0.0 0.5" /> 
            </material>
        </visual>
        <collision>
            <origin xyz="0 0 0" rpy="0 0 0"/>
            <geometry>
                <cylinder length="0.025" radius="0.035"/>
            </geometry>
            <material name="black">
                <color rgba="0.0 0.0 0.0 0.5" /> 
            </material>
        </collision>
    </link>
  
    <joint name="laser_joint" type="fixed">
        <parent link="base_link" />
        <child link="laser_link" />
        <origin xyz="0.084 0 0.0795" />
    </joint>

    <link name="camera_link">
  	    <visual>
            <origin xyz="0 0 0.0" rpy="0 0 0"/>
            <geometry>
		        <box size="0.065 0.165 0.03"/>
            </geometry>
            <material name="black">
                <color rgba="1.0 1.0 1.0 1.0"/>
            </material>
        </visual>
        <collision>
            <origin xyz="0 0 0.0" rpy="0 0 0"/>
            <geometry>
		        <box size="0.04 0.165 0.03"/>
            </geometry>
            <material name="black">
                <color rgba="1.0 1.0 1.0 1.0"/>
            </material>
        </collision>
    </link>

    <joint name="camera_joint" type="fixed">
        <parent link="base_link" />
        <child link="camera_link" />
        <origin xyz="0.119 0 0.03" />
    </joint>

    <link name="camera_link_optical"/>

    <joint name="camera_optical_joint" type="fixed">
        <parent link="camera_link"/>
        <child link="camera_link_optical"/>
        <origin rpy="-1.5707963267948966 0 -1.5707963267948966" xyz="0 0 0"/>
    </joint>

    <link name="imu_link">
        <visual>
            <origin xyz="0 0 0.0" rpy="0 0 0"/>
            <geometry>
                <box size="0.01 0.01 0.01"/>
            </geometry>
            <material name="blue">
                <color rgba="0.5 0.5 1 0.8" /> 
            </material>
        </visual>
        <collision>
            <origin xyz="0 0 0.0" rpy="0 0 0"/>
            <geometry>
                <box size="0.01 0.01 0.01"/>
            </geometry>
            <material name="blue">
      	        <color rgba="0.5 0.5 1 0.8" /> 
            </material>
        </collision>
    </link>

    <joint name="imu_joint" type="fixed">
        <parent link="base_link"/>
        <child link="imu_link"/>
        <origin xyz="0.0 0.0 0.0" rpy="0 0 0"/>
    </joint>

<!-- wheels inertia needs modified -->
    <link name="front_left_wheel_link">
        <visual>
            <origin xyz="0 0 0" rpy="1.57079 0 0"/>
                <geometry>
                    <cylinder length="0.0304" radius="0.0325"/>
                </geometry>
                <material name="black">
                    <color rgba="0.0 0.0 0.0 0.5" /> 
                </material>
        </visual>
        <collision>
            <origin xyz="0 0 0" rpy="1.57079 0 0"/>
            <geometry>
               <cylinder length="0.0304" radius="0.0325"/>
            </geometry>
            <material name="black">
                <color rgba="0.0 0.0 0.0 0.5" /> 
            </material>
        </collision>
        <inertial>
            <mass value="0.2"/>
            <inertia ixx="0.000190416666667" ixy="0" ixz="0" iyy="0.0001904" iyz="0" izz="0.00036"/>
        </inertial>
    </link>
    
    <joint name="front_left_wheel_joint" type="continuous">
        <parent link="base_link" />
        <child link="front_left_wheel_link" />
        <origin xyz="-0.08 0.0693 -0.0795" />
        <axis xyz="0 1 0" />
    </joint>

    <link name="front_right_wheel_link">
        <visual>
            <origin xyz="0 0 0" rpy="1.57079 0 0"/>
            <geometry>
                <cylinder length="0.0304" radius="0.0325"/>
            </geometry>
            <material name="black">
                <color rgba="0.0 0.0 0.0 0.5" /> 
            </material>
        </visual>
        <collision>
            <origin xyz="0 0 0" rpy="1.57079 0 0"/>
            <geometry>
                <cylinder length="0.0304" radius="0.0325"/>
            </geometry>
            <material name="black">
                <color rgba="0.0 0.0 0.0 0.5" /> 
            </material>
        </collision>
        <inertial>
            <mass value="0.2"/>
            <inertia ixx="0.000190416666667" ixy="0" ixz="0" iyy="0.0001904" iyz="0" izz="0.00036"/>
        </inertial>
    </link>
    
    <joint name="front_right_wheel_joint" type="continuous">
        <parent link="base_link" />
        <child link="front_right_wheel_link" />
        <origin xyz="0.08 0.0693 -0.0795" />
        <axis xyz="0 1 0" />
    </joint>
        
    <link name="rear_left_wheel_link">
        <visual>
            <origin xyz="0 0 0" rpy="1.57079 0 0"/>
            <geometry>
                <cylinder length="0.0304" radius="0.0325"/>
            </geometry>
            <material name="black">
                <color rgba="0.0 0.0 0.0 0.5" /> 
            </material>
        </visual>
        <collision>
            <origin xyz="0 0 0" rpy="1.57079 0 0"/>
            <geometry>
                <cylinder length="0.0304" radius="0.0325"/>
            </geometry>
            <material name="black">
                <color rgba="0.0 0.0 0.0 0.5" /> 
            </material>
        </collision>
        <inertial>
            <mass value="0.2"/>
            <inertia ixx="0.000190416666667" ixy="0" ixz="0" iyy="0.0001904" iyz="0" izz="0.00036"/>
        </inertial>
    </link>
        
    <joint name="rear_left_wheel_joint" type="continuous">
        <parent link="base_link" />
        <child link="rear_left_wheel_link" />
        <origin xyz="-0.08 -0.0693 -0.0795" />
        <axis xyz="0 1 0" />
    </joint>

    <link name="rear_right_wheel_link">
        <visual>
            <origin xyz="0 0 0" rpy="1.57079 0 0"/>
            <geometry>
                <cylinder length="0.0304" radius="0.0325"/>
            </geometry>
            <material name="black">
                <color rgba="0.0 0.0 0.0 0.5" /> 
            </material>
        </visual>
        <collision>
            <origin xyz="0 0 0" rpy="1.57079 0 0"/>
            <geometry>
                <cylinder length="0.0304" radius="0.0325"/>
            </geometry>
            <material name="black">
                <color rgba="0.0 0.0 0.0 0.5" /> 
            </material>
        </collision>
        <inertial>
            <mass value="0.2"/>
            <inertia ixx="0.000190416666667" ixy="0" ixz="0" iyy="0.0001904" iyz="0" izz="0.00036"/>
        </inertial>
    </link>
        
    <joint name="rear_right_wheel_joint" type="continuous">
        <parent link="base_link" />
        <child link="rear_right_wheel_link" />
        <origin xyz="0.08 -0.0693 -0.0795" />
        <axis xyz="0 1 0" />
    </joint>

            <gazebo>
        <plugin name='diff_drive' filename='libgazebo_ros_diff_drive.so'>
            <ros>
                <namespace>/</namespace>
                <remapping>cmd_vel:=cmd_vel</remapping>
                <remapping>odom:=odom</remapping>
            </ros>
            <update_rate>5</update_rate>
            <!-- wheels -->
            <left_joint>front_left_wheel_joint</left_joint>
            <right_joint>front_right_wheel_joint</right_joint>
            <!-- kinematics -->
            <wheel_separation>0.2</wheel_separation>
            <wheel_diameter>0.065</wheel_diameter>
            <!-- limits -->
            <max_wheel_torque>20</max_wheel_torque>
            <max_wheel_acceleration>1.0</max_wheel_acceleration>
            <!-- output -->
            <publish_odom>true</publish_odom>
            <publish_odom_tf>true</publish_odom_tf>
            <publish_wheel_tf>false</publish_wheel_tf>
            <odometry_frame>odom</odometry_frame>
            <robot_base_frame>base_footprint</robot_base_frame>
        </plugin>

        <plugin name="joint_state" filename="libgazebo_ros_joint_state_publisher.so">
            <ros>
            <remapping>~/out:=joint_states</remapping>
            </ros>
            <update_rate>5</update_rate>
            <joint_name>front_left_wheel_joint</joint_name>
            <joint_name>front_right_wheel_joint</joint_name>
            <joint_name>rear_left_wheel_joint</joint_name>
            <joint_name>rear_right_wheel_joint</joint_name>
        </plugin>    
    </gazebo> 

        <gazebo reference="laser_link">
            <material>Gazebo/Black</material>
        </gazebo>
        
        <gazebo reference="imu_link">
        <sensor name="imu_sensor" type="imu">
        <plugin filename="libgazebo_ros_imu_sensor.so" name="imu_plugin">
            <ros>
                <namespace>/</namespace>
                <remapping>~/out:=imu</remapping>
            </ros>
            <initial_orientation_as_reference>false</initial_orientation_as_reference>
            </plugin>
            <always_on>true</always_on>
            <update_rate>5</update_rate>
            <visualize>true</visualize>
            <imu>
            <angular_velocity>
                <x>
                <noise type="gaussian">
                    <mean>0.0</mean>
                    <stddev>2e-4</stddev>
                    <bias_mean>0.0000075</bias_mean>
                    <bias_stddev>0.0000008</bias_stddev>
                </noise>
                </x>
                <y>
                <noise type="gaussian">
                    <mean>0.0</mean>
                    <stddev>2e-4</stddev>
                    <bias_mean>0.0000075</bias_mean>
                    <bias_stddev>0.0000008</bias_stddev>
                </noise>
                </y>
                <z>
                <noise type="gaussian">
                    <mean>0.0</mean>
                    <stddev>2e-4</stddev>
                    <bias_mean>0.0000075</bias_mean>
                    <bias_stddev>0.0000008</bias_stddev>
                </noise>
                </z>
            </angular_velocity>
            <linear_acceleration>
                <x>
                <noise type="gaussian">
                    <mean>0.0</mean>
                    <stddev>1.7e-2</stddev>
                    <bias_mean>0.1</bias_mean>
                    <bias_stddev>0.001</bias_stddev>
                </noise>
                </x>
                <y>
                <noise type="gaussian">
                    <mean>0.0</mean>
                    <stddev>1.7e-2</stddev>
                    <bias_mean>0.1</bias_mean>
                    <bias_stddev>0.001</bias_stddev>
                </noise>
                </y>
                <z>
                <noise type="gaussian">
                    <mean>0.0</mean>
                    <stddev>1.7e-2</stddev>
                    <bias_mean>0.1</bias_mean>
                    <bias_stddev>0.001</bias_stddev>
                </noise>
                </z>
            </linear_acceleration>
            </imu>
        </sensor>
        </gazebo>

    <gazebo reference="laser_link">
        <sensor name="laser_sensor" type="ray">
        <always_on>true</always_on>
        <visualize>true</visualize>
        <update_rate>5</update_rate>
        <pose>0 0 0.075 0 0 0</pose>
        <ray>
            <scan>
                <horizontal>
                <samples>360</samples>
                <resolution>1.000000</resolution>
                <min_angle>0.000000</min_angle>
                <max_angle>6.280000</max_angle>
                </horizontal>
            </scan>
            <range>
                <min>0.120000</min>
                <max>3.5</max>
                <resolution>0.015000</resolution>
            </range>
            <noise>
                <type>gaussian</type>
                <mean>0.0</mean>
                <stddev>0.01</stddev>
            </noise>
        </ray>

        <plugin name="laserscan" filename="libgazebo_ros_ray_sensor.so">
            <ros>
            <remapping>~/out:=scan</remapping>
            </ros>
            <output_type>sensor_msgs/LaserScan</output_type>
            <frame_name>laser_link</frame_name>
        </plugin>
        </sensor>
    </gazebo>

    <gazebo reference="camera_link">
        <sensor name="camera_sensor" type="depth">
        <plugin filename="libgazebo_ros_camera.so" name="depth_camera">
            <frame_name>camera_link_optical</frame_name>
        </plugin>
        <always_on>true</always_on>
        <update_rate>10</update_rate>
        <camera name="camera">
            <horizontal_fov>1.5809</horizontal_fov>
            <image>
            <format>R8G8B8</format>
            <width>640</width>
            <height>480</height>
            </image>
            <distortion>
            <k1>0.0</k1>
            <k2>0.0</k2>
            <k3>0.0</k3>
            <p1>0.0</p1>
            <p2>0.0</p2>
            <center>0.5 0.5</center>
            </distortion>
        </camera>
        </sensor>
    </gazebo>

</robot>
    